{
  "id": "CVE-2017-14503",
  "assigner": "cve@mitre.org",
  "Published": "2017-09-17T16:29:00.293Z",
  "Modified": "2018-12-28T15:29:01.097Z",
  "last-modified": "2018-12-28T15:29:01.097Z",
  "summary": "libarchive 3.3.2 suffers from an out-of-bounds read within lha_read_data_none() in archive_read_support_format_lha.c when extracting a specially crafted lha archive, related to lha_crc16.",
  "access": {
    "authentication": "NONE",
    "complexity": "MEDIUM",
    "vector": "NETWORK"
  },
  "impact": {
    "availability": "PARTIAL",
    "confidentiality": "NONE",
    "integrity": "NONE"
  },
  "cvss": 4.3,
  "exploitabilityScore": 8.6,
  "impactScore": 2.9,
  "cvss-vector": "AV:N/AC:M/Au:N/C:N/I:N/A:P",
  "references": [
    "https://access.redhat.com/errata/RHSA-2019:2298",
    "https://access.redhat.com/errata/RHSA-2019:3698",
    "https://bugs.debian.org/875960",
    "https://github.com/libarchive/libarchive/issues/948",
    "https://lists.debian.org/debian-lts-announce/2018/11/msg00037.html",
    "https://security.gentoo.org/glsa/201908-11",
    "https://usn.ubuntu.com/3736-1/",
    "https://www.debian.org/security/2018/dsa-4360"
  ],
  "vulnerable_configuration": [],
  "vulnerable_product": [],
  "vendors": [],
  "products": [],
  "vulnerable_product_stems": [],
  "vulnerable_configuration_stems": [],
  "cwe": "CWE-125",
  "vulnerable_configuration_cpe_2_2": []
}