{
  "id": "CVE-2021-46823",
  "assigner": "cve@mitre.org",
  "Published": "2022-06-18T14:15:08.173Z",
  "Modified": "2022-06-28T14:11:51.253Z",
  "last-modified": "2022-06-28T14:11:51.253Z",
  "summary": "python-ldap before 3.4.0 is vulnerable to a denial of service when ldap.schema is used for untrusted schema definitions, because of a regular expression denial of service (ReDoS) flaw in the LDAP schema parser. By sending crafted regex input, a remote authenticated attacker could exploit this vulnerability to cause a denial of service condition.",
  "access": {
    "authentication": "SINGLE",
    "complexity": "LOW",
    "vector": "NETWORK"
  },
  "impact": {
    "availability": "PARTIAL",
    "confidentiality": "NONE",
    "integrity": "NONE"
  },
  "cvss": 4.0,
  "exploitabilityScore": 8.0,
  "impactScore": 2.9,
  "cvss-vector": "AV:N/AC:L/Au:S/C:N/I:N/A:P",
  "references": [
    "https://exchange.xforce.ibmcloud.com/vulnerabilities/221507",
    "https://github.com/python-ldap/python-ldap/security/advisories/GHSA-r8wq-qrxc-hmcm"
  ],
  "vulnerable_configuration": [],
  "vulnerable_product": [],
  "vendors": [],
  "products": [],
  "vulnerable_product_stems": [],
  "vulnerable_configuration_stems": [],
  "cwe": "NVD-CWE-Other",
  "vulnerable_configuration_cpe_2_2": []
}