{
  "id": "CVE-2010-3495",
  "assigner": "cve@mitre.org",
  "Published": "2010-10-19T18:00:04.377Z",
  "Modified": "2011-01-22T05:43:28.58Z",
  "last-modified": "2011-01-22T05:43:28.58Z",
  "summary": "Race condition in ZEO/StorageServer.py in Zope Object Database (ZODB) before 3.10.0 allows remote attackers to cause a denial of service (daemon outage) by establishing and then immediately closing a TCP connection, leading to the accept function having an unexpected return value of None, an unexpected value of None for the address, or an ECONNABORTED, EAGAIN, or EWOULDBLOCK error, a related issue to CVE-2010-3492.",
  "access": {
    "authentication": "NONE",
    "complexity": "MEDIUM",
    "vector": "NETWORK"
  },
  "impact": {
    "availability": "PARTIAL",
    "confidentiality": "NONE",
    "integrity": "NONE"
  },
  "cvss": 4.3,
  "exploitabilityScore": 8.6,
  "impactScore": 2.9,
  "cvss-vector": "AV:N/AC:M/Au:N/C:N/I:N/A:P",
  "references": [
    "http://bugs.python.org/issue6706",
    "http://lists.opensuse.org/opensuse-security-announce/2010-12/msg00006.html",
    "http://pypi.python.org/pypi/ZODB3/3.10.0#id1",
    "http://www.openwall.com/lists/oss-security/2010/09/09/6",
    "http://www.openwall.com/lists/oss-security/2010/09/11/2",
    "http://www.openwall.com/lists/oss-security/2010/09/22/3",
    "http://www.openwall.com/lists/oss-security/2010/09/24/3",
    "https://bugs.launchpad.net/zodb/+bug/135108"
  ],
  "vulnerable_configuration": [],
  "vulnerable_product": [],
  "vendors": [],
  "products": [],
  "vulnerable_product_stems": [],
  "vulnerable_configuration_stems": [],
  "cwe": "CWE-362",
  "vulnerable_configuration_cpe_2_2": []
}