{
  "id": "CVE-2022-1289",
  "assigner": "cna@vuldb.com",
  "Published": "2022-04-10T14:15:07.847Z",
  "Modified": "2023-03-07T21:38:43.943Z",
  "last-modified": "2023-03-07T21:38:43.943Z",
  "summary": "A denial of service vulnerability was found in tildearrow Furnace. It has been classified as problematic. This is due to an incomplete fix of CVE-2022-1211. It is possible to initiate the attack remotely but it requires user interaction. The issue got fixed with the patch 0eb02422d5161767e9983bdaa5c429762d3477ce.",
  "access": {
    "authentication": "NONE",
    "complexity": "MEDIUM",
    "vector": "NETWORK"
  },
  "impact": {
    "availability": "PARTIAL",
    "confidentiality": "NONE",
    "integrity": "NONE"
  },
  "cvss": 4.3,
  "exploitabilityScore": 8.6,
  "impactScore": 2.9,
  "cvss-vector": "AV:N/AC:M/Au:N/C:N/I:N/A:P",
  "references": [
    "https://github.com/tildearrow/furnace/commit/0eb02422d5161767e9983bdaa5c429762d3477ce",
    "https://github.com/tildearrow/furnace/issues/325#issuecomment-1094139655",
    "https://vuldb.com/?id.196755"
  ],
  "vulnerable_configuration": [],
  "vulnerable_product": [],
  "vendors": [],
  "products": [],
  "vulnerable_product_stems": [],
  "vulnerable_configuration_stems": [],
  "cwe": "NVD-CWE-noinfo",
  "vulnerable_configuration_cpe_2_2": []
}